Traceback (most recent call last):
  File "../exps/mter_test.py", line 99, in <module>
    'data_multiplier': datam[task_id]} 
IndexError: list index out of range
